[generatebatch_update_batchlist] ERROR: NOT NULL constraint failed: fullfilment_batchlist.status_batch
Traceback (most recent call last):
  File "C:\Users\m3vil\OneDrive\Desktop\ERP.ALFA\venv\Lib\site-packages\django\db\backends\utils.py", line 105, in _execute
    return self.cursor.execute(sql, params)
           ^^^^^^^^^^^^^^^^^^^^^^^^^^^^^^^^
  File "C:\Users\m3vil\OneDrive\Desktop\ERP.ALFA\venv\Lib\site-packages\django\db\backends\sqlite3\base.py", line 360, in execute
    return super().execute(query, params)
           ^^^^^^^^^^^^^^^^^^^^^^^^^^^^^^
sqlite3.IntegrityError: NOT NULL constraint failed: fullfilment_batchlist.status_batch

The above exception was the direct cause of the following exception:

Traceback (most recent call last):
  File "C:\Users\m3vil\OneDrive\Desktop\ERP.ALFA\oms\views.py", line 147, in generatebatch_update_batchlist
    batchlist = BatchList.objects.create(nama_batch=nama_batch, status_batch=None)
                ^^^^^^^^^^^^^^^^^^^^^^^^^^^^^^^^^^^^^^^^^^^^^^^^^^^^^^^^^^^^^^^^^^
  File "C:\Users\m3vil\OneDrive\Desktop\ERP.ALFA\venv\Lib\site-packages\django\db\models\manager.py", line 87, in manager_method
    return getattr(self.get_queryset(), name)(*args, **kwargs)
           ^^^^^^^^^^^^^^^^^^^^^^^^^^^^^^^^^^^^^^^^^^^^^^^^^^^
  File "C:\Users\m3vil\OneDrive\Desktop\ERP.ALFA\venv\Lib\site-packages\django\db\models\query.py", line 663, in create
    obj.save(force_insert=True, using=self.db)
  File "C:\Users\m3vil\OneDrive\Desktop\ERP.ALFA\venv\Lib\site-packages\django\db\models\base.py", line 902, in save
    self.save_base(
  File "C:\Users\m3vil\OneDrive\Desktop\ERP.ALFA\venv\Lib\site-packages\django\db\models\base.py", line 1008, in save_base
    updated = self._save_table(
              ^^^^^^^^^^^^^^^^^
  File "C:\Users\m3vil\OneDrive\Desktop\ERP.ALFA\venv\Lib\site-packages\django\db\models\base.py", line 1169, in _save_table
    results = self._do_insert(
              ^^^^^^^^^^^^^^^^
  File "C:\Users\m3vil\OneDrive\Desktop\ERP.ALFA\venv\Lib\site-packages\django\db\models\base.py", line 1210, in _do_insert
    return manager._insert(
           ^^^^^^^^^^^^^^^^
  File "C:\Users\m3vil\OneDrive\Desktop\ERP.ALFA\venv\Lib\site-packages\django\db\models\manager.py", line 87, in manager_method
    return getattr(self.get_queryset(), name)(*args, **kwargs)
           ^^^^^^^^^^^^^^^^^^^^^^^^^^^^^^^^^^^^^^^^^^^^^^^^^^^
  File "C:\Users\m3vil\OneDrive\Desktop\ERP.ALFA\venv\Lib\site-packages\django\db\models\query.py", line 1864, in _insert
    return query.get_compiler(using=using).execute_sql(returning_fields)
           ^^^^^^^^^^^^^^^^^^^^^^^^^^^^^^^^^^^^^^^^^^^^^^^^^^^^^^^^^^^^^
  File "C:\Users\m3vil\OneDrive\Desktop\ERP.ALFA\venv\Lib\site-packages\django\db\models\sql\compiler.py", line 1882, in execute_sql
    cursor.execute(sql, params)
  File "C:\Users\m3vil\OneDrive\Desktop\ERP.ALFA\venv\Lib\site-packages\django\db\backends\utils.py", line 122, in execute
    return super().execute(sql, params)
           ^^^^^^^^^^^^^^^^^^^^^^^^^^^^
  File "C:\Users\m3vil\OneDrive\Desktop\ERP.ALFA\venv\Lib\site-packages\django\db\backends\utils.py", line 79, in execute
    return self._execute_with_wrappers(
           ^^^^^^^^^^^^^^^^^^^^^^^^^^^^
  File "C:\Users\m3vil\OneDrive\Desktop\ERP.ALFA\venv\Lib\site-packages\django\db\backends\utils.py", line 92, in _execute_with_wrappers
    return executor(sql, params, many, context)
           ^^^^^^^^^^^^^^^^^^^^^^^^^^^^^^^^^^^^
  File "C:\Users\m3vil\OneDrive\Desktop\ERP.ALFA\venv\Lib\site-packages\django\db\backends\utils.py", line 100, in _execute
    with self.db.wrap_database_errors:
         ^^^^^^^^^^^^^^^^^^^^^^^^^^^^
  File "C:\Users\m3vil\OneDrive\Desktop\ERP.ALFA\venv\Lib\site-packages\django\db\utils.py", line 91, in __exit__
    raise dj_exc_value.with_traceback(traceback) from exc_value
  File "C:\Users\m3vil\OneDrive\Desktop\ERP.ALFA\venv\Lib\site-packages\django\db\backends\utils.py", line 105, in _execute
    return self.cursor.execute(sql, params)
           ^^^^^^^^^^^^^^^^^^^^^^^^^^^^^^^^
  File "C:\Users\m3vil\OneDrive\Desktop\ERP.ALFA\venv\Lib\site-packages\django\db\backends\sqlite3\base.py", line 360, in execute
    return super().execute(query, params)
           ^^^^^^^^^^^^^^^^^^^^^^^^^^^^^^
django.db.utils.IntegrityError: NOT NULL constraint failed: fullfilment_batchlist.status_batch

[generatebatch_update_batchlist] ERROR: no such table: orders_ordercukup
Traceback (most recent call last):
  File "C:\Users\m3vil\OneDrive\Desktop\ERP.ALFA\venv\Lib\site-packages\django\db\backends\utils.py", line 105, in _execute
    return self.cursor.execute(sql, params)
           ^^^^^^^^^^^^^^^^^^^^^^^^^^^^^^^^
  File "C:\Users\m3vil\OneDrive\Desktop\ERP.ALFA\venv\Lib\site-packages\django\db\backends\sqlite3\base.py", line 360, in execute
    return super().execute(query, params)
           ^^^^^^^^^^^^^^^^^^^^^^^^^^^^^^
sqlite3.OperationalError: no such table: orders_ordercukup

The above exception was the direct cause of the following exception:

Traceback (most recent call last):
  File "C:\Users\m3vil\OneDrive\Desktop\ERP.ALFA\oms\views.py", line 188, in generatebatch_update_batchlist
    id_pesanan_pilih = set(OrderCukup.objects.values_list('id_pesanan', flat=True))
                       ^^^^^^^^^^^^^^^^^^^^^^^^^^^^^^^^^^^^^^^^^^^^^^^^^^^^^^^^^^^^
  File "C:\Users\m3vil\OneDrive\Desktop\ERP.ALFA\venv\Lib\site-packages\django\db\models\query.py", line 384, in __iter__
    self._fetch_all()
  File "C:\Users\m3vil\OneDrive\Desktop\ERP.ALFA\venv\Lib\site-packages\django\db\models\query.py", line 1945, in _fetch_all
    self._result_cache = list(self._iterable_class(self))
                         ^^^^^^^^^^^^^^^^^^^^^^^^^^^^^^^^
  File "C:\Users\m3vil\OneDrive\Desktop\ERP.ALFA\venv\Lib\site-packages\django\db\models\query.py", line 271, in __iter__
    for row in compiler.results_iter(
               ^^^^^^^^^^^^^^^^^^^^^^
  File "C:\Users\m3vil\OneDrive\Desktop\ERP.ALFA\venv\Lib\site-packages\django\db\models\sql\compiler.py", line 1572, in results_iter
    results = self.execute_sql(
              ^^^^^^^^^^^^^^^^^
  File "C:\Users\m3vil\OneDrive\Desktop\ERP.ALFA\venv\Lib\site-packages\django\db\models\sql\compiler.py", line 1623, in execute_sql
    cursor.execute(sql, params)
  File "C:\Users\m3vil\OneDrive\Desktop\ERP.ALFA\venv\Lib\site-packages\django\db\backends\utils.py", line 122, in execute
    return super().execute(sql, params)
           ^^^^^^^^^^^^^^^^^^^^^^^^^^^^
  File "C:\Users\m3vil\OneDrive\Desktop\ERP.ALFA\venv\Lib\site-packages\django\db\backends\utils.py", line 79, in execute
    return self._execute_with_wrappers(
           ^^^^^^^^^^^^^^^^^^^^^^^^^^^^
  File "C:\Users\m3vil\OneDrive\Desktop\ERP.ALFA\venv\Lib\site-packages\django\db\backends\utils.py", line 92, in _execute_with_wrappers
    return executor(sql, params, many, context)
           ^^^^^^^^^^^^^^^^^^^^^^^^^^^^^^^^^^^^
  File "C:\Users\m3vil\OneDrive\Desktop\ERP.ALFA\venv\Lib\site-packages\django\db\backends\utils.py", line 100, in _execute
    with self.db.wrap_database_errors:
         ^^^^^^^^^^^^^^^^^^^^^^^^^^^^
  File "C:\Users\m3vil\OneDrive\Desktop\ERP.ALFA\venv\Lib\site-packages\django\db\utils.py", line 91, in __exit__
    raise dj_exc_value.with_traceback(traceback) from exc_value
  File "C:\Users\m3vil\OneDrive\Desktop\ERP.ALFA\venv\Lib\site-packages\django\db\backends\utils.py", line 105, in _execute
    return self.cursor.execute(sql, params)
           ^^^^^^^^^^^^^^^^^^^^^^^^^^^^^^^^
  File "C:\Users\m3vil\OneDrive\Desktop\ERP.ALFA\venv\Lib\site-packages\django\db\backends\sqlite3\base.py", line 360, in execute
    return super().execute(query, params)
           ^^^^^^^^^^^^^^^^^^^^^^^^^^^^^^
django.db.utils.OperationalError: no such table: orders_ordercukup

[generatebatch_update_batchlist] ERROR: no such table: orders_ordercukup
Traceback (most recent call last):
  File "C:\Users\m3vil\OneDrive\Desktop\ERP.ALFA\venv\Lib\site-packages\django\db\backends\utils.py", line 105, in _execute
    return self.cursor.execute(sql, params)
           ^^^^^^^^^^^^^^^^^^^^^^^^^^^^^^^^
  File "C:\Users\m3vil\OneDrive\Desktop\ERP.ALFA\venv\Lib\site-packages\django\db\backends\sqlite3\base.py", line 360, in execute
    return super().execute(query, params)
           ^^^^^^^^^^^^^^^^^^^^^^^^^^^^^^
sqlite3.OperationalError: no such table: orders_ordercukup

The above exception was the direct cause of the following exception:

Traceback (most recent call last):
  File "C:\Users\m3vil\OneDrive\Desktop\ERP.ALFA\oms\views.py", line 188, in generatebatch_update_batchlist
    id_pesanan_pilih = set(OrderCukup.objects.values_list('id_pesanan', flat=True))
                       ^^^^^^^^^^^^^^^^^^^^^^^^^^^^^^^^^^^^^^^^^^^^^^^^^^^^^^^^^^^^
  File "C:\Users\m3vil\OneDrive\Desktop\ERP.ALFA\venv\Lib\site-packages\django\db\models\query.py", line 384, in __iter__
    self._fetch_all()
  File "C:\Users\m3vil\OneDrive\Desktop\ERP.ALFA\venv\Lib\site-packages\django\db\models\query.py", line 1945, in _fetch_all
    self._result_cache = list(self._iterable_class(self))
                         ^^^^^^^^^^^^^^^^^^^^^^^^^^^^^^^^
  File "C:\Users\m3vil\OneDrive\Desktop\ERP.ALFA\venv\Lib\site-packages\django\db\models\query.py", line 271, in __iter__
    for row in compiler.results_iter(
               ^^^^^^^^^^^^^^^^^^^^^^
  File "C:\Users\m3vil\OneDrive\Desktop\ERP.ALFA\venv\Lib\site-packages\django\db\models\sql\compiler.py", line 1572, in results_iter
    results = self.execute_sql(
              ^^^^^^^^^^^^^^^^^
  File "C:\Users\m3vil\OneDrive\Desktop\ERP.ALFA\venv\Lib\site-packages\django\db\models\sql\compiler.py", line 1623, in execute_sql
    cursor.execute(sql, params)
  File "C:\Users\m3vil\OneDrive\Desktop\ERP.ALFA\venv\Lib\site-packages\django\db\backends\utils.py", line 122, in execute
    return super().execute(sql, params)
           ^^^^^^^^^^^^^^^^^^^^^^^^^^^^
  File "C:\Users\m3vil\OneDrive\Desktop\ERP.ALFA\venv\Lib\site-packages\django\db\backends\utils.py", line 79, in execute
    return self._execute_with_wrappers(
           ^^^^^^^^^^^^^^^^^^^^^^^^^^^^
  File "C:\Users\m3vil\OneDrive\Desktop\ERP.ALFA\venv\Lib\site-packages\django\db\backends\utils.py", line 92, in _execute_with_wrappers
    return executor(sql, params, many, context)
           ^^^^^^^^^^^^^^^^^^^^^^^^^^^^^^^^^^^^
  File "C:\Users\m3vil\OneDrive\Desktop\ERP.ALFA\venv\Lib\site-packages\django\db\backends\utils.py", line 100, in _execute
    with self.db.wrap_database_errors:
         ^^^^^^^^^^^^^^^^^^^^^^^^^^^^
  File "C:\Users\m3vil\OneDrive\Desktop\ERP.ALFA\venv\Lib\site-packages\django\db\utils.py", line 91, in __exit__
    raise dj_exc_value.with_traceback(traceback) from exc_value
  File "C:\Users\m3vil\OneDrive\Desktop\ERP.ALFA\venv\Lib\site-packages\django\db\backends\utils.py", line 105, in _execute
    return self.cursor.execute(sql, params)
           ^^^^^^^^^^^^^^^^^^^^^^^^^^^^^^^^
  File "C:\Users\m3vil\OneDrive\Desktop\ERP.ALFA\venv\Lib\site-packages\django\db\backends\sqlite3\base.py", line 360, in execute
    return super().execute(query, params)
           ^^^^^^^^^^^^^^^^^^^^^^^^^^^^^^
django.db.utils.OperationalError: no such table: orders_ordercukup

[generatebatch_update_batchlist] ERROR: no such table: orders_ordercukup
Traceback (most recent call last):
  File "C:\Users\m3vil\OneDrive\Desktop\ERP.ALFA\venv\Lib\site-packages\django\db\backends\utils.py", line 105, in _execute
    return self.cursor.execute(sql, params)
           ^^^^^^^^^^^^^^^^^^^^^^^^^^^^^^^^
  File "C:\Users\m3vil\OneDrive\Desktop\ERP.ALFA\venv\Lib\site-packages\django\db\backends\sqlite3\base.py", line 360, in execute
    return super().execute(query, params)
           ^^^^^^^^^^^^^^^^^^^^^^^^^^^^^^
sqlite3.OperationalError: no such table: orders_ordercukup

The above exception was the direct cause of the following exception:

Traceback (most recent call last):
  File "C:\Users\m3vil\OneDrive\Desktop\ERP.ALFA\oms\views.py", line 189, in generatebatch_update_batchlist
    id_pesanan_pilih = set(OrderCukup.objects.values_list('id_pesanan', flat=True))
                       ^^^^^^^^^^^^^^^^^^^^^^^^^^^^^^^^^^^^^^^^^^^^^^^^^^^^^^^^^^^^
  File "C:\Users\m3vil\OneDrive\Desktop\ERP.ALFA\venv\Lib\site-packages\django\db\models\query.py", line 384, in __iter__
    self._fetch_all()
  File "C:\Users\m3vil\OneDrive\Desktop\ERP.ALFA\venv\Lib\site-packages\django\db\models\query.py", line 1945, in _fetch_all
    self._result_cache = list(self._iterable_class(self))
                         ^^^^^^^^^^^^^^^^^^^^^^^^^^^^^^^^
  File "C:\Users\m3vil\OneDrive\Desktop\ERP.ALFA\venv\Lib\site-packages\django\db\models\query.py", line 271, in __iter__
    for row in compiler.results_iter(
               ^^^^^^^^^^^^^^^^^^^^^^
  File "C:\Users\m3vil\OneDrive\Desktop\ERP.ALFA\venv\Lib\site-packages\django\db\models\sql\compiler.py", line 1572, in results_iter
    results = self.execute_sql(
              ^^^^^^^^^^^^^^^^^
  File "C:\Users\m3vil\OneDrive\Desktop\ERP.ALFA\venv\Lib\site-packages\django\db\models\sql\compiler.py", line 1623, in execute_sql
    cursor.execute(sql, params)
  File "C:\Users\m3vil\OneDrive\Desktop\ERP.ALFA\venv\Lib\site-packages\django\db\backends\utils.py", line 122, in execute
    return super().execute(sql, params)
           ^^^^^^^^^^^^^^^^^^^^^^^^^^^^
  File "C:\Users\m3vil\OneDrive\Desktop\ERP.ALFA\venv\Lib\site-packages\django\db\backends\utils.py", line 79, in execute
    return self._execute_with_wrappers(
           ^^^^^^^^^^^^^^^^^^^^^^^^^^^^
  File "C:\Users\m3vil\OneDrive\Desktop\ERP.ALFA\venv\Lib\site-packages\django\db\backends\utils.py", line 92, in _execute_with_wrappers
    return executor(sql, params, many, context)
           ^^^^^^^^^^^^^^^^^^^^^^^^^^^^^^^^^^^^
  File "C:\Users\m3vil\OneDrive\Desktop\ERP.ALFA\venv\Lib\site-packages\django\db\backends\utils.py", line 100, in _execute
    with self.db.wrap_database_errors:
         ^^^^^^^^^^^^^^^^^^^^^^^^^^^^
  File "C:\Users\m3vil\OneDrive\Desktop\ERP.ALFA\venv\Lib\site-packages\django\db\utils.py", line 91, in __exit__
    raise dj_exc_value.with_traceback(traceback) from exc_value
  File "C:\Users\m3vil\OneDrive\Desktop\ERP.ALFA\venv\Lib\site-packages\django\db\backends\utils.py", line 105, in _execute
    return self.cursor.execute(sql, params)
           ^^^^^^^^^^^^^^^^^^^^^^^^^^^^^^^^
  File "C:\Users\m3vil\OneDrive\Desktop\ERP.ALFA\venv\Lib\site-packages\django\db\backends\sqlite3\base.py", line 360, in execute
    return super().execute(query, params)
           ^^^^^^^^^^^^^^^^^^^^^^^^^^^^^^
django.db.utils.OperationalError: no such table: orders_ordercukup

[generatebatch_update_batchlist] ERROR: no such table: orders_ordercukup
Traceback (most recent call last):
  File "C:\Users\m3vil\OneDrive\Desktop\ERP.ALFA\venv\Lib\site-packages\django\db\backends\utils.py", line 105, in _execute
    return self.cursor.execute(sql, params)
           ^^^^^^^^^^^^^^^^^^^^^^^^^^^^^^^^
  File "C:\Users\m3vil\OneDrive\Desktop\ERP.ALFA\venv\Lib\site-packages\django\db\backends\sqlite3\base.py", line 360, in execute
    return super().execute(query, params)
           ^^^^^^^^^^^^^^^^^^^^^^^^^^^^^^
sqlite3.OperationalError: no such table: orders_ordercukup

The above exception was the direct cause of the following exception:

Traceback (most recent call last):
  File "C:\Users\m3vil\OneDrive\Desktop\ERP.ALFA\oms\views.py", line 151, in generatebatch_update_batchlist
    id_pesanan_pilih = set(OrderCukup.objects.values_list('id_pesanan', flat=True))
                       ^^^^^^^^^^^^^^^^^^^^^^^^^^^^^^^^^^^^^^^^^^^^^^^^^^^^^^^^^^^^
  File "C:\Users\m3vil\OneDrive\Desktop\ERP.ALFA\venv\Lib\site-packages\django\db\models\query.py", line 384, in __iter__
    self._fetch_all()
  File "C:\Users\m3vil\OneDrive\Desktop\ERP.ALFA\venv\Lib\site-packages\django\db\models\query.py", line 1945, in _fetch_all
    self._result_cache = list(self._iterable_class(self))
                         ^^^^^^^^^^^^^^^^^^^^^^^^^^^^^^^^
  File "C:\Users\m3vil\OneDrive\Desktop\ERP.ALFA\venv\Lib\site-packages\django\db\models\query.py", line 271, in __iter__
    for row in compiler.results_iter(
               ^^^^^^^^^^^^^^^^^^^^^^
  File "C:\Users\m3vil\OneDrive\Desktop\ERP.ALFA\venv\Lib\site-packages\django\db\models\sql\compiler.py", line 1572, in results_iter
    results = self.execute_sql(
              ^^^^^^^^^^^^^^^^^
  File "C:\Users\m3vil\OneDrive\Desktop\ERP.ALFA\venv\Lib\site-packages\django\db\models\sql\compiler.py", line 1623, in execute_sql
    cursor.execute(sql, params)
  File "C:\Users\m3vil\OneDrive\Desktop\ERP.ALFA\venv\Lib\site-packages\django\db\backends\utils.py", line 122, in execute
    return super().execute(sql, params)
           ^^^^^^^^^^^^^^^^^^^^^^^^^^^^
  File "C:\Users\m3vil\OneDrive\Desktop\ERP.ALFA\venv\Lib\site-packages\django\db\backends\utils.py", line 79, in execute
    return self._execute_with_wrappers(
           ^^^^^^^^^^^^^^^^^^^^^^^^^^^^
  File "C:\Users\m3vil\OneDrive\Desktop\ERP.ALFA\venv\Lib\site-packages\django\db\backends\utils.py", line 92, in _execute_with_wrappers
    return executor(sql, params, many, context)
           ^^^^^^^^^^^^^^^^^^^^^^^^^^^^^^^^^^^^
  File "C:\Users\m3vil\OneDrive\Desktop\ERP.ALFA\venv\Lib\site-packages\django\db\backends\utils.py", line 100, in _execute
    with self.db.wrap_database_errors:
         ^^^^^^^^^^^^^^^^^^^^^^^^^^^^
  File "C:\Users\m3vil\OneDrive\Desktop\ERP.ALFA\venv\Lib\site-packages\django\db\utils.py", line 91, in __exit__
    raise dj_exc_value.with_traceback(traceback) from exc_value
  File "C:\Users\m3vil\OneDrive\Desktop\ERP.ALFA\venv\Lib\site-packages\django\db\backends\utils.py", line 105, in _execute
    return self.cursor.execute(sql, params)
           ^^^^^^^^^^^^^^^^^^^^^^^^^^^^^^^^
  File "C:\Users\m3vil\OneDrive\Desktop\ERP.ALFA\venv\Lib\site-packages\django\db\backends\sqlite3\base.py", line 360, in execute
    return super().execute(query, params)
           ^^^^^^^^^^^^^^^^^^^^^^^^^^^^^^
django.db.utils.OperationalError: no such table: orders_ordercukup

[generatebatch_update_batchlist] ERROR: not all arguments converted during string formatting
Traceback (most recent call last):
  File "C:\Users\m3vil\OneDrive\Desktop\ERP.ALFA\oms\views.py", line 186, in generatebatch_update_batchlist
    cursor.execute(sql, params)
  File "C:\Users\m3vil\OneDrive\Desktop\ERP.ALFA\venv\Lib\site-packages\django\db\backends\utils.py", line 121, in execute
    with self.debug_sql(sql, params, use_last_executed_query=True):
         ^^^^^^^^^^^^^^^^^^^^^^^^^^^^^^^^^^^^^^^^^^^^^^^^^^^^^^^^^
  File "C:\Program Files\WindowsApps\PythonSoftwareFoundation.Python.3.12_3.12.2800.0_x64__qbz5n2kfra8p0\Lib\contextlib.py", line 144, in __exit__
    next(self.gen)
  File "C:\Users\m3vil\OneDrive\Desktop\ERP.ALFA\venv\Lib\site-packages\django\db\backends\utils.py", line 139, in debug_sql
    sql = self.db.ops.last_executed_query(self.cursor, sql, params)
          ^^^^^^^^^^^^^^^^^^^^^^^^^^^^^^^^^^^^^^^^^^^^^^^^^^^^^^^^^
  File "C:\Users\m3vil\OneDrive\Desktop\ERP.ALFA\venv\Lib\site-packages\django\db\backends\sqlite3\operations.py", line 193, in last_executed_query
    return sql % params
           ~~~~^~~~~~~~
TypeError: not all arguments converted during string formatting

[generatebatch_update_batchlist] ERROR: not all arguments converted during string formatting
Traceback (most recent call last):
  File "C:\Users\m3vil\OneDrive\Desktop\ERP.ALFA\oms\views.py", line 186, in generatebatch_update_batchlist
    cursor.execute(sql, params)
  File "C:\Users\m3vil\OneDrive\Desktop\ERP.ALFA\venv\Lib\site-packages\django\db\backends\utils.py", line 121, in execute
    with self.debug_sql(sql, params, use_last_executed_query=True):
         ^^^^^^^^^^^^^^^^^^^^^^^^^^^^^^^^^^^^^^^^^^^^^^^^^^^^^^^^^
  File "C:\Program Files\WindowsApps\PythonSoftwareFoundation.Python.3.12_3.12.2800.0_x64__qbz5n2kfra8p0\Lib\contextlib.py", line 144, in __exit__
    next(self.gen)
  File "C:\Users\m3vil\OneDrive\Desktop\ERP.ALFA\venv\Lib\site-packages\django\db\backends\utils.py", line 139, in debug_sql
    sql = self.db.ops.last_executed_query(self.cursor, sql, params)
          ^^^^^^^^^^^^^^^^^^^^^^^^^^^^^^^^^^^^^^^^^^^^^^^^^^^^^^^^^
  File "C:\Users\m3vil\OneDrive\Desktop\ERP.ALFA\venv\Lib\site-packages\django\db\backends\sqlite3\operations.py", line 193, in last_executed_query
    return sql % params
           ~~~~^~~~~~~~
TypeError: not all arguments converted during string formatting

[generatebatch_update_batchlist] ERROR: not all arguments converted during string formatting
Traceback (most recent call last):
  File "C:\Users\m3vil\OneDrive\Desktop\ERP.ALFA\oms\views.py", line 174, in generatebatch_update_batchlist
    cursor.execute(sql, params)
  File "C:\Users\m3vil\OneDrive\Desktop\ERP.ALFA\venv\Lib\site-packages\django\db\backends\utils.py", line 121, in execute
    with self.debug_sql(sql, params, use_last_executed_query=True):
         ^^^^^^^^^^^^^^^^^^^^^^^^^^^^^^^^^^^^^^^^^^^^^^^^^^^^^^^^^
  File "C:\Program Files\WindowsApps\PythonSoftwareFoundation.Python.3.12_3.12.2800.0_x64__qbz5n2kfra8p0\Lib\contextlib.py", line 144, in __exit__
    next(self.gen)
  File "C:\Users\m3vil\OneDrive\Desktop\ERP.ALFA\venv\Lib\site-packages\django\db\backends\utils.py", line 139, in debug_sql
    sql = self.db.ops.last_executed_query(self.cursor, sql, params)
          ^^^^^^^^^^^^^^^^^^^^^^^^^^^^^^^^^^^^^^^^^^^^^^^^^^^^^^^^^
  File "C:\Users\m3vil\OneDrive\Desktop\ERP.ALFA\venv\Lib\site-packages\django\db\backends\sqlite3\operations.py", line 193, in last_executed_query
    return sql % params
           ~~~~^~~~~~~~
TypeError: not all arguments converted during string formatting

[generatebatch_update_batchlist] ERROR: not all arguments converted during string formatting
Traceback (most recent call last):
  File "C:\Users\m3vil\OneDrive\Desktop\ERP.ALFA\oms\views.py", line 174, in generatebatch_update_batchlist
    cursor.execute(sql, params)
  File "C:\Users\m3vil\OneDrive\Desktop\ERP.ALFA\venv\Lib\site-packages\django\db\backends\utils.py", line 121, in execute
    with self.debug_sql(sql, params, use_last_executed_query=True):
         ^^^^^^^^^^^^^^^^^^^^^^^^^^^^^^^^^^^^^^^^^^^^^^^^^^^^^^^^^
  File "C:\Program Files\WindowsApps\PythonSoftwareFoundation.Python.3.12_3.12.2800.0_x64__qbz5n2kfra8p0\Lib\contextlib.py", line 144, in __exit__
    next(self.gen)
  File "C:\Users\m3vil\OneDrive\Desktop\ERP.ALFA\venv\Lib\site-packages\django\db\backends\utils.py", line 139, in debug_sql
    sql = self.db.ops.last_executed_query(self.cursor, sql, params)
          ^^^^^^^^^^^^^^^^^^^^^^^^^^^^^^^^^^^^^^^^^^^^^^^^^^^^^^^^^
  File "C:\Users\m3vil\OneDrive\Desktop\ERP.ALFA\venv\Lib\site-packages\django\db\backends\sqlite3\operations.py", line 193, in last_executed_query
    return sql % params
           ~~~~^~~~~~~~
TypeError: not all arguments converted during string formatting

[generatebatch_update_batchlist] ERROR: not all arguments converted during string formatting
Traceback (most recent call last):
  File "C:\Users\m3vil\OneDrive\Desktop\ERP.ALFA\oms\views.py", line 180, in generatebatch_update_batchlist
    cursor.execute(sql, params)
  File "C:\Users\m3vil\OneDrive\Desktop\ERP.ALFA\venv\Lib\site-packages\django\db\backends\utils.py", line 121, in execute
    with self.debug_sql(sql, params, use_last_executed_query=True):
         ^^^^^^^^^^^^^^^^^^^^^^^^^^^^^^^^^^^^^^^^^^^^^^^^^^^^^^^^^
  File "C:\Program Files\WindowsApps\PythonSoftwareFoundation.Python.3.12_3.12.2800.0_x64__qbz5n2kfra8p0\Lib\contextlib.py", line 144, in __exit__
    next(self.gen)
  File "C:\Users\m3vil\OneDrive\Desktop\ERP.ALFA\venv\Lib\site-packages\django\db\backends\utils.py", line 139, in debug_sql
    sql = self.db.ops.last_executed_query(self.cursor, sql, params)
          ^^^^^^^^^^^^^^^^^^^^^^^^^^^^^^^^^^^^^^^^^^^^^^^^^^^^^^^^^
  File "C:\Users\m3vil\OneDrive\Desktop\ERP.ALFA\venv\Lib\site-packages\django\db\backends\sqlite3\operations.py", line 193, in last_executed_query
    return sql % params
           ~~~~^~~~~~~~
TypeError: not all arguments converted during string formatting

[generatebatch_update_batchlist] ERROR: not all arguments converted during string formatting
Traceback (most recent call last):
  File "C:\Users\m3vil\OneDrive\Desktop\ERP.ALFA\oms\views.py", line 180, in generatebatch_update_batchlist
    cursor.execute(sql, params)
  File "C:\Users\m3vil\OneDrive\Desktop\ERP.ALFA\venv\Lib\site-packages\django\db\backends\utils.py", line 121, in execute
    with self.debug_sql(sql, params, use_last_executed_query=True):
         ^^^^^^^^^^^^^^^^^^^^^^^^^^^^^^^^^^^^^^^^^^^^^^^^^^^^^^^^^
  File "C:\Program Files\WindowsApps\PythonSoftwareFoundation.Python.3.12_3.12.2800.0_x64__qbz5n2kfra8p0\Lib\contextlib.py", line 144, in __exit__
    next(self.gen)
  File "C:\Users\m3vil\OneDrive\Desktop\ERP.ALFA\venv\Lib\site-packages\django\db\backends\utils.py", line 139, in debug_sql
    sql = self.db.ops.last_executed_query(self.cursor, sql, params)
          ^^^^^^^^^^^^^^^^^^^^^^^^^^^^^^^^^^^^^^^^^^^^^^^^^^^^^^^^^
  File "C:\Users\m3vil\OneDrive\Desktop\ERP.ALFA\venv\Lib\site-packages\django\db\backends\sqlite3\operations.py", line 193, in last_executed_query
    return sql % params
           ~~~~^~~~~~~~
TypeError: not all arguments converted during string formatting

[generatebatch_update_batchlist] ERROR: not all arguments converted during string formatting
Traceback (most recent call last):
  File "C:\Users\m3vil\OneDrive\Desktop\ERP.ALFA\oms\views.py", line 180, in generatebatch_update_batchlist
    cursor.execute(sql, params)
  File "C:\Users\m3vil\OneDrive\Desktop\ERP.ALFA\venv\Lib\site-packages\django\db\backends\utils.py", line 121, in execute
    with self.debug_sql(sql, params, use_last_executed_query=True):
         ^^^^^^^^^^^^^^^^^^^^^^^^^^^^^^^^^^^^^^^^^^^^^^^^^^^^^^^^^
  File "C:\Program Files\WindowsApps\PythonSoftwareFoundation.Python.3.12_3.12.2800.0_x64__qbz5n2kfra8p0\Lib\contextlib.py", line 144, in __exit__
    next(self.gen)
  File "C:\Users\m3vil\OneDrive\Desktop\ERP.ALFA\venv\Lib\site-packages\django\db\backends\utils.py", line 139, in debug_sql
    sql = self.db.ops.last_executed_query(self.cursor, sql, params)
          ^^^^^^^^^^^^^^^^^^^^^^^^^^^^^^^^^^^^^^^^^^^^^^^^^^^^^^^^^
  File "C:\Users\m3vil\OneDrive\Desktop\ERP.ALFA\venv\Lib\site-packages\django\db\backends\sqlite3\operations.py", line 193, in last_executed_query
    return sql % params
           ~~~~^~~~~~~~
TypeError: not all arguments converted during string formatting

[generatebatch_update_batchlist] ERROR: not all arguments converted during string formatting
Traceback (most recent call last):
  File "C:\Users\m3vil\OneDrive\Desktop\ERP.ALFA\oms\views.py", line 180, in generatebatch_update_batchlist
    cursor.execute(sql, params)
  File "C:\Users\m3vil\OneDrive\Desktop\ERP.ALFA\venv\Lib\site-packages\django\db\backends\utils.py", line 121, in execute
    with self.debug_sql(sql, params, use_last_executed_query=True):
         ^^^^^^^^^^^^^^^^^^^^^^^^^^^^^^^^^^^^^^^^^^^^^^^^^^^^^^^^^
  File "C:\Program Files\WindowsApps\PythonSoftwareFoundation.Python.3.12_3.12.2800.0_x64__qbz5n2kfra8p0\Lib\contextlib.py", line 144, in __exit__
    next(self.gen)
  File "C:\Users\m3vil\OneDrive\Desktop\ERP.ALFA\venv\Lib\site-packages\django\db\backends\utils.py", line 139, in debug_sql
    sql = self.db.ops.last_executed_query(self.cursor, sql, params)
          ^^^^^^^^^^^^^^^^^^^^^^^^^^^^^^^^^^^^^^^^^^^^^^^^^^^^^^^^^
  File "C:\Users\m3vil\OneDrive\Desktop\ERP.ALFA\venv\Lib\site-packages\django\db\backends\sqlite3\operations.py", line 193, in last_executed_query
    return sql % params
           ~~~~^~~~~~~~
TypeError: not all arguments converted during string formatting

[generatebatch_update_batchlist] ERROR: not all arguments converted during string formatting
Traceback (most recent call last):
  File "C:\Users\m3vil\OneDrive\Desktop\ERP.ALFA\oms\views.py", line 180, in generatebatch_update_batchlist
    cursor.execute(sql, params)
  File "C:\Users\m3vil\OneDrive\Desktop\ERP.ALFA\venv\Lib\site-packages\django\db\backends\utils.py", line 121, in execute
    with self.debug_sql(sql, params, use_last_executed_query=True):
         ^^^^^^^^^^^^^^^^^^^^^^^^^^^^^^^^^^^^^^^^^^^^^^^^^^^^^^^^^
  File "C:\Program Files\WindowsApps\PythonSoftwareFoundation.Python.3.12_3.12.2800.0_x64__qbz5n2kfra8p0\Lib\contextlib.py", line 144, in __exit__
    next(self.gen)
  File "C:\Users\m3vil\OneDrive\Desktop\ERP.ALFA\venv\Lib\site-packages\django\db\backends\utils.py", line 139, in debug_sql
    sql = self.db.ops.last_executed_query(self.cursor, sql, params)
          ^^^^^^^^^^^^^^^^^^^^^^^^^^^^^^^^^^^^^^^^^^^^^^^^^^^^^^^^^
  File "C:\Users\m3vil\OneDrive\Desktop\ERP.ALFA\venv\Lib\site-packages\django\db\backends\sqlite3\operations.py", line 193, in last_executed_query
    return sql % params
           ~~~~^~~~~~~~
TypeError: not all arguments converted during string formatting

[generatebatch_update_batchlist] ERROR: not all arguments converted during string formatting
Traceback (most recent call last):
  File "C:\Users\m3vil\OneDrive\Desktop\ERP.ALFA\oms\views.py", line 180, in generatebatch_update_batchlist
    cursor.execute(sql, params)
  File "C:\Users\m3vil\OneDrive\Desktop\ERP.ALFA\venv\Lib\site-packages\django\db\backends\utils.py", line 121, in execute
    with self.debug_sql(sql, params, use_last_executed_query=True):
         ^^^^^^^^^^^^^^^^^^^^^^^^^^^^^^^^^^^^^^^^^^^^^^^^^^^^^^^^^
  File "C:\Program Files\WindowsApps\PythonSoftwareFoundation.Python.3.12_3.12.2800.0_x64__qbz5n2kfra8p0\Lib\contextlib.py", line 144, in __exit__
    next(self.gen)
  File "C:\Users\m3vil\OneDrive\Desktop\ERP.ALFA\venv\Lib\site-packages\django\db\backends\utils.py", line 139, in debug_sql
    sql = self.db.ops.last_executed_query(self.cursor, sql, params)
          ^^^^^^^^^^^^^^^^^^^^^^^^^^^^^^^^^^^^^^^^^^^^^^^^^^^^^^^^^
  File "C:\Users\m3vil\OneDrive\Desktop\ERP.ALFA\venv\Lib\site-packages\django\db\backends\sqlite3\operations.py", line 193, in last_executed_query
    return sql % params
           ~~~~^~~~~~~~
TypeError: not all arguments converted during string formatting

[generatebatch_update_batchlist] ERROR: not all arguments converted during string formatting
Traceback (most recent call last):
  File "C:\Users\m3vil\OneDrive\Desktop\ERP.ALFA\oms\views.py", line 180, in generatebatch_update_batchlist
    cursor.execute(sql, params)
  File "C:\Users\m3vil\OneDrive\Desktop\ERP.ALFA\venv\Lib\site-packages\django\db\backends\utils.py", line 121, in execute
    with self.debug_sql(sql, params, use_last_executed_query=True):
         ^^^^^^^^^^^^^^^^^^^^^^^^^^^^^^^^^^^^^^^^^^^^^^^^^^^^^^^^^
  File "C:\Program Files\WindowsApps\PythonSoftwareFoundation.Python.3.12_3.12.2800.0_x64__qbz5n2kfra8p0\Lib\contextlib.py", line 144, in __exit__
    next(self.gen)
  File "C:\Users\m3vil\OneDrive\Desktop\ERP.ALFA\venv\Lib\site-packages\django\db\backends\utils.py", line 139, in debug_sql
    sql = self.db.ops.last_executed_query(self.cursor, sql, params)
          ^^^^^^^^^^^^^^^^^^^^^^^^^^^^^^^^^^^^^^^^^^^^^^^^^^^^^^^^^
  File "C:\Users\m3vil\OneDrive\Desktop\ERP.ALFA\venv\Lib\site-packages\django\db\backends\sqlite3\operations.py", line 193, in last_executed_query
    return sql % params
           ~~~~^~~~~~~~
TypeError: not all arguments converted during string formatting

[generatebatch_update_batchlist] ERROR: not all arguments converted during string formatting
Traceback (most recent call last):
  File "C:\Users\m3vil\OneDrive\Desktop\ERP.ALFA\oms\views.py", line 180, in generatebatch_update_batchlist
    cursor.execute(sql, params)
  File "C:\Users\m3vil\OneDrive\Desktop\ERP.ALFA\venv\Lib\site-packages\django\db\backends\utils.py", line 121, in execute
    with self.debug_sql(sql, params, use_last_executed_query=True):
         ^^^^^^^^^^^^^^^^^^^^^^^^^^^^^^^^^^^^^^^^^^^^^^^^^^^^^^^^^
  File "C:\Program Files\WindowsApps\PythonSoftwareFoundation.Python.3.12_3.12.2800.0_x64__qbz5n2kfra8p0\Lib\contextlib.py", line 144, in __exit__
    next(self.gen)
  File "C:\Users\m3vil\OneDrive\Desktop\ERP.ALFA\venv\Lib\site-packages\django\db\backends\utils.py", line 139, in debug_sql
    sql = self.db.ops.last_executed_query(self.cursor, sql, params)
          ^^^^^^^^^^^^^^^^^^^^^^^^^^^^^^^^^^^^^^^^^^^^^^^^^^^^^^^^^
  File "C:\Users\m3vil\OneDrive\Desktop\ERP.ALFA\venv\Lib\site-packages\django\db\backends\sqlite3\operations.py", line 193, in last_executed_query
    return sql % params
           ~~~~^~~~~~~~
TypeError: not all arguments converted during string formatting

[generatebatch_update_batchlist] ERROR: not all arguments converted during string formatting
Traceback (most recent call last):
  File "C:\Users\m3vil\OneDrive\Desktop\ERP.ALFA\oms\views.py", line 180, in generatebatch_update_batchlist
    cursor.execute(sql, params)
  File "C:\Users\m3vil\OneDrive\Desktop\ERP.ALFA\venv\Lib\site-packages\django\db\backends\utils.py", line 121, in execute
    with self.debug_sql(sql, params, use_last_executed_query=True):
         ^^^^^^^^^^^^^^^^^^^^^^^^^^^^^^^^^^^^^^^^^^^^^^^^^^^^^^^^^
  File "C:\Program Files\WindowsApps\PythonSoftwareFoundation.Python.3.12_3.12.2800.0_x64__qbz5n2kfra8p0\Lib\contextlib.py", line 144, in __exit__
    next(self.gen)
  File "C:\Users\m3vil\OneDrive\Desktop\ERP.ALFA\venv\Lib\site-packages\django\db\backends\utils.py", line 139, in debug_sql
    sql = self.db.ops.last_executed_query(self.cursor, sql, params)
          ^^^^^^^^^^^^^^^^^^^^^^^^^^^^^^^^^^^^^^^^^^^^^^^^^^^^^^^^^
  File "C:\Users\m3vil\OneDrive\Desktop\ERP.ALFA\venv\Lib\site-packages\django\db\backends\sqlite3\operations.py", line 193, in last_executed_query
    return sql % params
           ~~~~^~~~~~~~
TypeError: not all arguments converted during string formatting

[generatebatch_update_batchlist] ERROR: not all arguments converted during string formatting
Traceback (most recent call last):
  File "C:\Users\m3vil\OneDrive\Desktop\ERP.ALFA\fullfilment\generatebatch_views.py", line 183, in generatebatch_update_batchlist
    cursor.execute(sql, params)
  File "C:\Users\m3vil\OneDrive\Desktop\ERP.ALFA\venv\Lib\site-packages\django\db\backends\utils.py", line 121, in execute
    with self.debug_sql(sql, params, use_last_executed_query=True):
         ^^^^^^^^^^^^^^^^^^^^^^^^^^^^^^^^^^^^^^^^^^^^^^^^^^^^^^^^^
  File "C:\Program Files\WindowsApps\PythonSoftwareFoundation.Python.3.12_3.12.2800.0_x64__qbz5n2kfra8p0\Lib\contextlib.py", line 144, in __exit__
    next(self.gen)
  File "C:\Users\m3vil\OneDrive\Desktop\ERP.ALFA\venv\Lib\site-packages\django\db\backends\utils.py", line 139, in debug_sql
    sql = self.db.ops.last_executed_query(self.cursor, sql, params)
          ^^^^^^^^^^^^^^^^^^^^^^^^^^^^^^^^^^^^^^^^^^^^^^^^^^^^^^^^^
  File "C:\Users\m3vil\OneDrive\Desktop\ERP.ALFA\venv\Lib\site-packages\django\db\backends\sqlite3\operations.py", line 193, in last_executed_query
    return sql % params
           ~~~~^~~~~~~~
TypeError: not all arguments converted during string formatting

[generatebatch_update_batchlist] ERROR: not all arguments converted during string formatting
Traceback (most recent call last):
  File "C:\Users\m3vil\OneDrive\Desktop\ERP.ALFA\fullfilment\generatebatch_views.py", line 206, in generatebatch_update_batchlist
    cursor.execute(sql, params)
  File "C:\Users\m3vil\OneDrive\Desktop\ERP.ALFA\venv\Lib\site-packages\django\db\backends\utils.py", line 121, in execute
    with self.debug_sql(sql, params, use_last_executed_query=True):
         ^^^^^^^^^^^^^^^^^^^^^^^^^^^^^^^^^^^^^^^^^^^^^^^^^^^^^^^^^
  File "C:\Program Files\WindowsApps\PythonSoftwareFoundation.Python.3.12_3.12.2800.0_x64__qbz5n2kfra8p0\Lib\contextlib.py", line 144, in __exit__
    next(self.gen)
  File "C:\Users\m3vil\OneDrive\Desktop\ERP.ALFA\venv\Lib\site-packages\django\db\backends\utils.py", line 139, in debug_sql
    sql = self.db.ops.last_executed_query(self.cursor, sql, params)
          ^^^^^^^^^^^^^^^^^^^^^^^^^^^^^^^^^^^^^^^^^^^^^^^^^^^^^^^^^
  File "C:\Users\m3vil\OneDrive\Desktop\ERP.ALFA\venv\Lib\site-packages\django\db\backends\sqlite3\operations.py", line 193, in last_executed_query
    return sql % params
           ~~~~^~~~~~~~
TypeError: not all arguments converted during string formatting

[generatebatch_update_batchlist] ERROR: not all arguments converted during string formatting
Traceback (most recent call last):
  File "C:\Users\m3vil\OneDrive\Desktop\ERP.ALFA\fullfilment\generatebatch_views.py", line 206, in generatebatch_update_batchlist
    cursor.execute(sql, params)
  File "C:\Users\m3vil\OneDrive\Desktop\ERP.ALFA\venv\Lib\site-packages\django\db\backends\utils.py", line 121, in execute
    with self.debug_sql(sql, params, use_last_executed_query=True):
         ^^^^^^^^^^^^^^^^^^^^^^^^^^^^^^^^^^^^^^^^^^^^^^^^^^^^^^^^^
  File "C:\Program Files\WindowsApps\PythonSoftwareFoundation.Python.3.12_3.12.2800.0_x64__qbz5n2kfra8p0\Lib\contextlib.py", line 144, in __exit__
    next(self.gen)
  File "C:\Users\m3vil\OneDrive\Desktop\ERP.ALFA\venv\Lib\site-packages\django\db\backends\utils.py", line 139, in debug_sql
    sql = self.db.ops.last_executed_query(self.cursor, sql, params)
          ^^^^^^^^^^^^^^^^^^^^^^^^^^^^^^^^^^^^^^^^^^^^^^^^^^^^^^^^^
  File "C:\Users\m3vil\OneDrive\Desktop\ERP.ALFA\venv\Lib\site-packages\django\db\backends\sqlite3\operations.py", line 193, in last_executed_query
    return sql % params
           ~~~~^~~~~~~~
TypeError: not all arguments converted during string formatting

[generatebatch_update_batchlist] ERROR: not all arguments converted during string formatting
Traceback (most recent call last):
  File "C:\Users\m3vil\OneDrive\Desktop\ERP.ALFA\fullfilment\generatebatch_views.py", line 206, in generatebatch_update_batchlist
    cursor.execute(sql, params)
  File "C:\Users\m3vil\OneDrive\Desktop\ERP.ALFA\venv\Lib\site-packages\django\db\backends\utils.py", line 121, in execute
    with self.debug_sql(sql, params, use_last_executed_query=True):
         ^^^^^^^^^^^^^^^^^^^^^^^^^^^^^^^^^^^^^^^^^^^^^^^^^^^^^^^^^
  File "C:\Program Files\WindowsApps\PythonSoftwareFoundation.Python.3.12_3.12.2800.0_x64__qbz5n2kfra8p0\Lib\contextlib.py", line 144, in __exit__
    next(self.gen)
  File "C:\Users\m3vil\OneDrive\Desktop\ERP.ALFA\venv\Lib\site-packages\django\db\backends\utils.py", line 139, in debug_sql
    sql = self.db.ops.last_executed_query(self.cursor, sql, params)
          ^^^^^^^^^^^^^^^^^^^^^^^^^^^^^^^^^^^^^^^^^^^^^^^^^^^^^^^^^
  File "C:\Users\m3vil\OneDrive\Desktop\ERP.ALFA\venv\Lib\site-packages\django\db\backends\sqlite3\operations.py", line 193, in last_executed_query
    return sql % params
           ~~~~^~~~~~~~
TypeError: not all arguments converted during string formatting

[generatebatch_update_batchlist] ERROR: not all arguments converted during string formatting
Traceback (most recent call last):
  File "C:\Users\m3vil\OneDrive\Desktop\ERP.ALFA\fullfilment\generatebatch_views.py", line 206, in generatebatch_update_batchlist
    cursor.execute(sql, params)
  File "C:\Users\m3vil\OneDrive\Desktop\ERP.ALFA\venv\Lib\site-packages\django\db\backends\utils.py", line 121, in execute
    with self.debug_sql(sql, params, use_last_executed_query=True):
         ^^^^^^^^^^^^^^^^^^^^^^^^^^^^^^^^^^^^^^^^^^^^^^^^^^^^^^^^^
  File "C:\Program Files\WindowsApps\PythonSoftwareFoundation.Python.3.12_3.12.2800.0_x64__qbz5n2kfra8p0\Lib\contextlib.py", line 144, in __exit__
    next(self.gen)
  File "C:\Users\m3vil\OneDrive\Desktop\ERP.ALFA\venv\Lib\site-packages\django\db\backends\utils.py", line 139, in debug_sql
    sql = self.db.ops.last_executed_query(self.cursor, sql, params)
          ^^^^^^^^^^^^^^^^^^^^^^^^^^^^^^^^^^^^^^^^^^^^^^^^^^^^^^^^^
  File "C:\Users\m3vil\OneDrive\Desktop\ERP.ALFA\venv\Lib\site-packages\django\db\backends\sqlite3\operations.py", line 193, in last_executed_query
    return sql % params
           ~~~~^~~~~~~~
TypeError: not all arguments converted during string formatting

[generatebatch_update_batchlist] ERROR: not all arguments converted during string formatting
Traceback (most recent call last):
  File "C:\Users\m3vil\OneDrive\Desktop\ERP.ALFA\fullfilment\generatebatch_views.py", line 206, in generatebatch_update_batchlist
    cursor.execute(sql, params)
  File "C:\Users\m3vil\OneDrive\Desktop\ERP.ALFA\venv\Lib\site-packages\django\db\backends\utils.py", line 121, in execute
    with self.debug_sql(sql, params, use_last_executed_query=True):
         ^^^^^^^^^^^^^^^^^^^^^^^^^^^^^^^^^^^^^^^^^^^^^^^^^^^^^^^^^
  File "C:\Program Files\WindowsApps\PythonSoftwareFoundation.Python.3.12_3.12.2800.0_x64__qbz5n2kfra8p0\Lib\contextlib.py", line 144, in __exit__
    next(self.gen)
  File "C:\Users\m3vil\OneDrive\Desktop\ERP.ALFA\venv\Lib\site-packages\django\db\backends\utils.py", line 139, in debug_sql
    sql = self.db.ops.last_executed_query(self.cursor, sql, params)
          ^^^^^^^^^^^^^^^^^^^^^^^^^^^^^^^^^^^^^^^^^^^^^^^^^^^^^^^^^
  File "C:\Users\m3vil\OneDrive\Desktop\ERP.ALFA\venv\Lib\site-packages\django\db\backends\sqlite3\operations.py", line 193, in last_executed_query
    return sql % params
           ~~~~^~~~~~~~
TypeError: not all arguments converted during string formatting

[generatebatch_update_batchlist] ERROR: not all arguments converted during string formatting
Traceback (most recent call last):
  File "C:\Users\m3vil\OneDrive\Desktop\ERP.ALFA\fullfilment\generatebatch_views.py", line 206, in generatebatch_update_batchlist
    cursor.execute(sql, params)
  File "C:\Users\m3vil\OneDrive\Desktop\ERP.ALFA\venv\Lib\site-packages\django\db\backends\utils.py", line 121, in execute
    with self.debug_sql(sql, params, use_last_executed_query=True):
         ^^^^^^^^^^^^^^^^^^^^^^^^^^^^^^^^^^^^^^^^^^^^^^^^^^^^^^^^^
  File "C:\Program Files\WindowsApps\PythonSoftwareFoundation.Python.3.12_3.12.2800.0_x64__qbz5n2kfra8p0\Lib\contextlib.py", line 144, in __exit__
    next(self.gen)
  File "C:\Users\m3vil\OneDrive\Desktop\ERP.ALFA\venv\Lib\site-packages\django\db\backends\utils.py", line 139, in debug_sql
    sql = self.db.ops.last_executed_query(self.cursor, sql, params)
          ^^^^^^^^^^^^^^^^^^^^^^^^^^^^^^^^^^^^^^^^^^^^^^^^^^^^^^^^^
  File "C:\Users\m3vil\OneDrive\Desktop\ERP.ALFA\venv\Lib\site-packages\django\db\backends\sqlite3\operations.py", line 193, in last_executed_query
    return sql % params
           ~~~~^~~~~~~~
TypeError: not all arguments converted during string formatting

[generatebatch_update_batchlist] ERROR: not all arguments converted during string formatting
Traceback (most recent call last):
  File "C:\Users\m3vil\OneDrive\Desktop\ERP.ALFA\fullfilment\generatebatch_views.py", line 206, in generatebatch_update_batchlist
    cursor.execute(sql, params)
  File "C:\Users\m3vil\OneDrive\Desktop\ERP.ALFA\venv\Lib\site-packages\django\db\backends\utils.py", line 121, in execute
    with self.debug_sql(sql, params, use_last_executed_query=True):
         ^^^^^^^^^^^^^^^^^^^^^^^^^^^^^^^^^^^^^^^^^^^^^^^^^^^^^^^^^
  File "C:\Program Files\WindowsApps\PythonSoftwareFoundation.Python.3.12_3.12.2800.0_x64__qbz5n2kfra8p0\Lib\contextlib.py", line 144, in __exit__
    next(self.gen)
  File "C:\Users\m3vil\OneDrive\Desktop\ERP.ALFA\venv\Lib\site-packages\django\db\backends\utils.py", line 139, in debug_sql
    sql = self.db.ops.last_executed_query(self.cursor, sql, params)
          ^^^^^^^^^^^^^^^^^^^^^^^^^^^^^^^^^^^^^^^^^^^^^^^^^^^^^^^^^
  File "C:\Users\m3vil\OneDrive\Desktop\ERP.ALFA\venv\Lib\site-packages\django\db\backends\sqlite3\operations.py", line 193, in last_executed_query
    return sql % params
           ~~~~^~~~~~~~
TypeError: not all arguments converted during string formatting

[generatebatch_update_batchlist] ERROR: not all arguments converted during string formatting
Traceback (most recent call last):
  File "C:\Users\m3vil\OneDrive\Desktop\ERP.ALFA\fullfilment\generatebatch_views.py", line 206, in generatebatch_update_batchlist
    cursor.execute(sql, params)
  File "C:\Users\m3vil\OneDrive\Desktop\ERP.ALFA\venv\Lib\site-packages\django\db\backends\utils.py", line 121, in execute
    with self.debug_sql(sql, params, use_last_executed_query=True):
         ^^^^^^^^^^^^^^^^^^^^^^^^^^^^^^^^^^^^^^^^^^^^^^^^^^^^^^^^^
  File "C:\Program Files\WindowsApps\PythonSoftwareFoundation.Python.3.12_3.12.2800.0_x64__qbz5n2kfra8p0\Lib\contextlib.py", line 144, in __exit__
    next(self.gen)
  File "C:\Users\m3vil\OneDrive\Desktop\ERP.ALFA\venv\Lib\site-packages\django\db\backends\utils.py", line 139, in debug_sql
    sql = self.db.ops.last_executed_query(self.cursor, sql, params)
          ^^^^^^^^^^^^^^^^^^^^^^^^^^^^^^^^^^^^^^^^^^^^^^^^^^^^^^^^^
  File "C:\Users\m3vil\OneDrive\Desktop\ERP.ALFA\venv\Lib\site-packages\django\db\backends\sqlite3\operations.py", line 193, in last_executed_query
    return sql % params
           ~~~~^~~~~~~~
TypeError: not all arguments converted during string formatting

[generatebatch_update_batchlist] ERROR: not all arguments converted during string formatting
Traceback (most recent call last):
  File "C:\Users\m3vil\OneDrive\Desktop\ERP.ALFA\fullfilment\generatebatch_views.py", line 206, in generatebatch_update_batchlist
    cursor.execute(sql, params)
  File "C:\Users\m3vil\OneDrive\Desktop\ERP.ALFA\venv\Lib\site-packages\django\db\backends\utils.py", line 121, in execute
    with self.debug_sql(sql, params, use_last_executed_query=True):
         ^^^^^^^^^^^^^^^^^^^^^^^^^^^^^^^^^^^^^^^^^^^^^^^^^^^^^^^^^
  File "C:\Program Files\WindowsApps\PythonSoftwareFoundation.Python.3.12_3.12.2800.0_x64__qbz5n2kfra8p0\Lib\contextlib.py", line 144, in __exit__
    next(self.gen)
  File "C:\Users\m3vil\OneDrive\Desktop\ERP.ALFA\venv\Lib\site-packages\django\db\backends\utils.py", line 139, in debug_sql
    sql = self.db.ops.last_executed_query(self.cursor, sql, params)
          ^^^^^^^^^^^^^^^^^^^^^^^^^^^^^^^^^^^^^^^^^^^^^^^^^^^^^^^^^
  File "C:\Users\m3vil\OneDrive\Desktop\ERP.ALFA\venv\Lib\site-packages\django\db\backends\sqlite3\operations.py", line 193, in last_executed_query
    return sql % params
           ~~~~^~~~~~~~
TypeError: not all arguments converted during string formatting

[generatebatch_update_batchlist] ERROR: not all arguments converted during string formatting
Traceback (most recent call last):
  File "C:\Users\m3vil\OneDrive\Desktop\ERP.ALFA\fullfilment\generatebatch_views.py", line 206, in generatebatch_update_batchlist
    cursor.execute(sql, params)
  File "C:\Users\m3vil\OneDrive\Desktop\ERP.ALFA\venv\Lib\site-packages\django\db\backends\utils.py", line 121, in execute
    with self.debug_sql(sql, params, use_last_executed_query=True):
         ^^^^^^^^^^^^^^^^^^^^^^^^^^^^^^^^^^^^^^^^^^^^^^^^^^^^^^^^^
  File "C:\Program Files\WindowsApps\PythonSoftwareFoundation.Python.3.12_3.12.2800.0_x64__qbz5n2kfra8p0\Lib\contextlib.py", line 144, in __exit__
    next(self.gen)
  File "C:\Users\m3vil\OneDrive\Desktop\ERP.ALFA\venv\Lib\site-packages\django\db\backends\utils.py", line 139, in debug_sql
    sql = self.db.ops.last_executed_query(self.cursor, sql, params)
          ^^^^^^^^^^^^^^^^^^^^^^^^^^^^^^^^^^^^^^^^^^^^^^^^^^^^^^^^^
  File "C:\Users\m3vil\OneDrive\Desktop\ERP.ALFA\venv\Lib\site-packages\django\db\backends\sqlite3\operations.py", line 193, in last_executed_query
    return sql % params
           ~~~~^~~~~~~~
TypeError: not all arguments converted during string formatting

[generatebatch_update_batchlist] ERROR: not all arguments converted during string formatting
Traceback (most recent call last):
  File "C:\Users\m3vil\OneDrive\Desktop\ERP.ALFA\fullfilment\generatebatch_views.py", line 206, in generatebatch_update_batchlist
    cursor.execute(sql, params)
  File "C:\Users\m3vil\OneDrive\Desktop\ERP.ALFA\venv\Lib\site-packages\django\db\backends\utils.py", line 121, in execute
    with self.debug_sql(sql, params, use_last_executed_query=True):
         ^^^^^^^^^^^^^^^^^^^^^^^^^^^^^^^^^^^^^^^^^^^^^^^^^^^^^^^^^
  File "C:\Program Files\WindowsApps\PythonSoftwareFoundation.Python.3.12_3.12.2800.0_x64__qbz5n2kfra8p0\Lib\contextlib.py", line 144, in __exit__
    next(self.gen)
  File "C:\Users\m3vil\OneDrive\Desktop\ERP.ALFA\venv\Lib\site-packages\django\db\backends\utils.py", line 139, in debug_sql
    sql = self.db.ops.last_executed_query(self.cursor, sql, params)
          ^^^^^^^^^^^^^^^^^^^^^^^^^^^^^^^^^^^^^^^^^^^^^^^^^^^^^^^^^
  File "C:\Users\m3vil\OneDrive\Desktop\ERP.ALFA\venv\Lib\site-packages\django\db\backends\sqlite3\operations.py", line 193, in last_executed_query
    return sql % params
           ~~~~^~~~~~~~
TypeError: not all arguments converted during string formatting

[generatebatch_update_batchlist] ERROR: not all arguments converted during string formatting
Traceback (most recent call last):
  File "C:\Users\m3vil\OneDrive\Desktop\ERP.ALFA\fullfilment\generatebatch_views.py", line 214, in generatebatch_update_batchlist
    cursor.execute(sql, params)
  File "C:\Users\m3vil\OneDrive\Desktop\ERP.ALFA\venv\Lib\site-packages\django\db\backends\utils.py", line 121, in execute
    with self.debug_sql(sql, params, use_last_executed_query=True):
         ^^^^^^^^^^^^^^^^^^^^^^^^^^^^^^^^^^^^^^^^^^^^^^^^^^^^^^^^^
  File "C:\Program Files\WindowsApps\PythonSoftwareFoundation.Python.3.12_3.12.2800.0_x64__qbz5n2kfra8p0\Lib\contextlib.py", line 144, in __exit__
    next(self.gen)
  File "C:\Users\m3vil\OneDrive\Desktop\ERP.ALFA\venv\Lib\site-packages\django\db\backends\utils.py", line 139, in debug_sql
    sql = self.db.ops.last_executed_query(self.cursor, sql, params)
          ^^^^^^^^^^^^^^^^^^^^^^^^^^^^^^^^^^^^^^^^^^^^^^^^^^^^^^^^^
  File "C:\Users\m3vil\OneDrive\Desktop\ERP.ALFA\venv\Lib\site-packages\django\db\backends\sqlite3\operations.py", line 193, in last_executed_query
    return sql % params
           ~~~~^~~~~~~~
TypeError: not all arguments converted during string formatting

[generatebatch_update_batchlist] ERROR: not all arguments converted during string formatting
Traceback (most recent call last):
  File "C:\Users\m3vil\OneDrive\Desktop\ERP.ALFA\fullfilment\generatebatch_views.py", line 214, in generatebatch_update_batchlist
    cursor.execute(sql, params)
  File "C:\Users\m3vil\OneDrive\Desktop\ERP.ALFA\venv\Lib\site-packages\django\db\backends\utils.py", line 121, in execute
    with self.debug_sql(sql, params, use_last_executed_query=True):
         ^^^^^^^^^^^^^^^^^^^^^^^^^^^^^^^^^^^^^^^^^^^^^^^^^^^^^^^^^
  File "C:\Program Files\WindowsApps\PythonSoftwareFoundation.Python.3.12_3.12.2800.0_x64__qbz5n2kfra8p0\Lib\contextlib.py", line 144, in __exit__
    next(self.gen)
  File "C:\Users\m3vil\OneDrive\Desktop\ERP.ALFA\venv\Lib\site-packages\django\db\backends\utils.py", line 139, in debug_sql
    sql = self.db.ops.last_executed_query(self.cursor, sql, params)
          ^^^^^^^^^^^^^^^^^^^^^^^^^^^^^^^^^^^^^^^^^^^^^^^^^^^^^^^^^
  File "C:\Users\m3vil\OneDrive\Desktop\ERP.ALFA\venv\Lib\site-packages\django\db\backends\sqlite3\operations.py", line 193, in last_executed_query
    return sql % params
           ~~~~^~~~~~~~
TypeError: not all arguments converted during string formatting

[generatebatch_update_batchlist] ERROR: not all arguments converted during string formatting
Traceback (most recent call last):
  File "C:\Users\m3vil\OneDrive\Desktop\ERP.ALFA\fullfilment\generatebatch_views.py", line 214, in generatebatch_update_batchlist
    cursor.execute(sql, params)
  File "C:\Users\m3vil\OneDrive\Desktop\ERP.ALFA\venv\Lib\site-packages\django\db\backends\utils.py", line 121, in execute
    with self.debug_sql(sql, params, use_last_executed_query=True):
         ^^^^^^^^^^^^^^^^^^^^^^^^^^^^^^^^^^^^^^^^^^^^^^^^^^^^^^^^^
  File "C:\Program Files\WindowsApps\PythonSoftwareFoundation.Python.3.12_3.12.2800.0_x64__qbz5n2kfra8p0\Lib\contextlib.py", line 144, in __exit__
    next(self.gen)
  File "C:\Users\m3vil\OneDrive\Desktop\ERP.ALFA\venv\Lib\site-packages\django\db\backends\utils.py", line 139, in debug_sql
    sql = self.db.ops.last_executed_query(self.cursor, sql, params)
          ^^^^^^^^^^^^^^^^^^^^^^^^^^^^^^^^^^^^^^^^^^^^^^^^^^^^^^^^^
  File "C:\Users\m3vil\OneDrive\Desktop\ERP.ALFA\venv\Lib\site-packages\django\db\backends\sqlite3\operations.py", line 193, in last_executed_query
    return sql % params
           ~~~~^~~~~~~~
TypeError: not all arguments converted during string formatting

[generatebatch_update_batchlist] ERROR: not all arguments converted during string formatting
Traceback (most recent call last):
  File "C:\Users\m3vil\OneDrive\Desktop\ERP.ALFA\fullfilment\generatebatch_views.py", line 214, in generatebatch_update_batchlist
    cursor.execute(sql, params)
  File "C:\Users\m3vil\OneDrive\Desktop\ERP.ALFA\venv\Lib\site-packages\django\db\backends\utils.py", line 121, in execute
    with self.debug_sql(sql, params, use_last_executed_query=True):
         ^^^^^^^^^^^^^^^^^^^^^^^^^^^^^^^^^^^^^^^^^^^^^^^^^^^^^^^^^
  File "C:\Program Files\WindowsApps\PythonSoftwareFoundation.Python.3.12_3.12.2800.0_x64__qbz5n2kfra8p0\Lib\contextlib.py", line 144, in __exit__
    next(self.gen)
  File "C:\Users\m3vil\OneDrive\Desktop\ERP.ALFA\venv\Lib\site-packages\django\db\backends\utils.py", line 139, in debug_sql
    sql = self.db.ops.last_executed_query(self.cursor, sql, params)
          ^^^^^^^^^^^^^^^^^^^^^^^^^^^^^^^^^^^^^^^^^^^^^^^^^^^^^^^^^
  File "C:\Users\m3vil\OneDrive\Desktop\ERP.ALFA\venv\Lib\site-packages\django\db\backends\sqlite3\operations.py", line 193, in last_executed_query
    return sql % params
           ~~~~^~~~~~~~
TypeError: not all arguments converted during string formatting

[generatebatch_update_batchlist] ERROR: syntax error at or near "WHERE"
LINE 1: UPDATE orders_order SET nama_batch = ? WHERE id_pesanan IN (...
                                               ^

Traceback (most recent call last):
  File "C:\Users\m3vil\OneDrive\Desktop\ERP.ALFA\venv\Lib\site-packages\django\db\backends\utils.py", line 105, in _execute
    return self.cursor.execute(sql, params)
           ^^^^^^^^^^^^^^^^^^^^^^^^^^^^^^^^
psycopg2.errors.SyntaxError: syntax error at or near "WHERE"
LINE 1: UPDATE orders_order SET nama_batch = ? WHERE id_pesanan IN (...
                                               ^


The above exception was the direct cause of the following exception:

Traceback (most recent call last):
  File "C:\Users\m3vil\OneDrive\Desktop\ERP.ALFA\fullfilment\generatebatch_views.py", line 214, in generatebatch_update_batchlist
    cursor.execute(sql, params)
  File "C:\Users\m3vil\OneDrive\Desktop\ERP.ALFA\venv\Lib\site-packages\django\db\backends\utils.py", line 122, in execute
    return super().execute(sql, params)
           ^^^^^^^^^^^^^^^^^^^^^^^^^^^^
  File "C:\Users\m3vil\OneDrive\Desktop\ERP.ALFA\venv\Lib\site-packages\django\db\backends\utils.py", line 79, in execute
    return self._execute_with_wrappers(
           ^^^^^^^^^^^^^^^^^^^^^^^^^^^^
  File "C:\Users\m3vil\OneDrive\Desktop\ERP.ALFA\venv\Lib\site-packages\django\db\backends\utils.py", line 92, in _execute_with_wrappers
    return executor(sql, params, many, context)
           ^^^^^^^^^^^^^^^^^^^^^^^^^^^^^^^^^^^^
  File "C:\Users\m3vil\OneDrive\Desktop\ERP.ALFA\venv\Lib\site-packages\django\db\backends\utils.py", line 100, in _execute
    with self.db.wrap_database_errors:
         ^^^^^^^^^^^^^^^^^^^^^^^^^^^^
  File "C:\Users\m3vil\OneDrive\Desktop\ERP.ALFA\venv\Lib\site-packages\django\db\utils.py", line 91, in __exit__
    raise dj_exc_value.with_traceback(traceback) from exc_value
  File "C:\Users\m3vil\OneDrive\Desktop\ERP.ALFA\venv\Lib\site-packages\django\db\backends\utils.py", line 105, in _execute
    return self.cursor.execute(sql, params)
           ^^^^^^^^^^^^^^^^^^^^^^^^^^^^^^^^
django.db.utils.ProgrammingError: syntax error at or near "WHERE"
LINE 1: UPDATE orders_order SET nama_batch = ? WHERE id_pesanan IN (...
                                               ^


[generatebatch_update_batchlist] ERROR: syntax error at or near "WHERE"
LINE 1: UPDATE orders_order SET nama_batch = ? WHERE id_pesanan IN (...
                                               ^

Traceback (most recent call last):
  File "C:\Users\m3vil\OneDrive\Desktop\ERP.ALFA\venv\Lib\site-packages\django\db\backends\utils.py", line 105, in _execute
    return self.cursor.execute(sql, params)
           ^^^^^^^^^^^^^^^^^^^^^^^^^^^^^^^^
psycopg2.errors.SyntaxError: syntax error at or near "WHERE"
LINE 1: UPDATE orders_order SET nama_batch = ? WHERE id_pesanan IN (...
                                               ^


The above exception was the direct cause of the following exception:

Traceback (most recent call last):
  File "C:\Users\m3vil\OneDrive\Desktop\ERP.ALFA\fullfilment\generatebatch_views.py", line 214, in generatebatch_update_batchlist
    cursor.execute(sql, params)
  File "C:\Users\m3vil\OneDrive\Desktop\ERP.ALFA\venv\Lib\site-packages\django\db\backends\utils.py", line 122, in execute
    return super().execute(sql, params)
           ^^^^^^^^^^^^^^^^^^^^^^^^^^^^
  File "C:\Users\m3vil\OneDrive\Desktop\ERP.ALFA\venv\Lib\site-packages\django\db\backends\utils.py", line 79, in execute
    return self._execute_with_wrappers(
           ^^^^^^^^^^^^^^^^^^^^^^^^^^^^
  File "C:\Users\m3vil\OneDrive\Desktop\ERP.ALFA\venv\Lib\site-packages\django\db\backends\utils.py", line 92, in _execute_with_wrappers
    return executor(sql, params, many, context)
           ^^^^^^^^^^^^^^^^^^^^^^^^^^^^^^^^^^^^
  File "C:\Users\m3vil\OneDrive\Desktop\ERP.ALFA\venv\Lib\site-packages\django\db\backends\utils.py", line 100, in _execute
    with self.db.wrap_database_errors:
         ^^^^^^^^^^^^^^^^^^^^^^^^^^^^
  File "C:\Users\m3vil\OneDrive\Desktop\ERP.ALFA\venv\Lib\site-packages\django\db\utils.py", line 91, in __exit__
    raise dj_exc_value.with_traceback(traceback) from exc_value
  File "C:\Users\m3vil\OneDrive\Desktop\ERP.ALFA\venv\Lib\site-packages\django\db\backends\utils.py", line 105, in _execute
    return self.cursor.execute(sql, params)
           ^^^^^^^^^^^^^^^^^^^^^^^^^^^^^^^^
django.db.utils.ProgrammingError: syntax error at or near "WHERE"
LINE 1: UPDATE orders_order SET nama_batch = ? WHERE id_pesanan IN (...
                                               ^


